Workbook

Sheet 🏠 Cover
B1: 📊 📈 📉 💹 🧮 📋 📌 ✨ 🎯 🚀
B2: 🎓 FINAL PRACTICAL EXAM 🎓
B6: 📊 Excel Interactive Dashboard Project 📈
B8: 🔢 📑 🧹 📊 🧮 📈 🎛️ 📝 ✅
B10: 👤 Name | C10: Disha Thakkar
B11: 🆔 GR ID | C11: 12782
B12: 📚 Course | C12: Data Analysis with Excel
B13: 📅 Date | C13: 15-Oct-2026
B14: ⏱️ Time Limit | C14: 3 hours
B15: 🗂️ Dataset | C15: Retail Sales 2025 (sample dataset, India)
B16: 💾 Submit As | C16: DishaThakkar_ExcelDashboard.xlsx
B18: 🟨 Yellow cells on this page = personal details
B19: 🗺️ CONTENTS (click to jump) 👇
B20: 📺 Dashboard | C20: 🎛️ Interactive dashboard with dropdown filters
B21: 📋 Instructions | C21: 📌 Exam rules & instructions
B22: ✅ Tasks | C22: 🎯 7 tasks, time estimates, weightage
B23: 📥 Raw_Data | C23: 🗑️ Original messy dataset (duplicates, blanks, text dates)
B24: 🧹 Clean_Data | C24: ✨ Cleaned data + cleaning log + calculated columns
B25: 📊 Pivots | C25: 🧩 Pivot-style summary tables + conditional formatting
B26: 🧮 Formulas | C26: 🧠 VLOOKUP, INDEX-MATCH, IF, nested functions
B27: 📈 Charts | C27: 🥧 Charts: bar, line, pie, clustered, horizontal
B28: 📝 Documentation | C28: 📖 Naming conventions, assumptions, how-to
B30: 🛠️ Skills: Import • Cleaning • Pivots • Formulas • Charts • Dashboard • Documentation
B31: 🌟 Best of Luck! 🌟 ✅ Made with ❤️ in Excel 💚
B32: 💰 📦 🛒 🧾 📅 🌍 🏆 ⭐ 🎉 🥳

Sheet 📺 Dashboard
B1: 🎓 📊 SALES PERFORMANCE DASHBOARD 2025 📈 🎓
B3: 👤 Disha Thakkar | 🆔 GR ID 12782 | 📅 15-Oct-2026 | 📊 Excel Interactive Dashboard | O3: helper
B4: 🌍 Region | C4: All | E4: 📦 Category | F4: All | H4: 👥 Segment | I4: All | O4: =IF(C4="All","*",C4) -> *
B5: 💰 📦 🛒 🧾 📅 🌍 🏆 ⭐ 📈 📉 💹 🎯 | O5: =IF(F4="All","*",F4) -> *
B6: 👆 Use the yellow dropdowns to filter — every KPI, table and chart updates instantly (Excel Slicer-style). | O6: =IF(I4="All","*",I4) -> *
B7: 💰 Total Sales | D7: 📈 Total Profit | F7: 🧾 Orders | H7: 🛒 Avg Order Value | J7: 📊 Profit Margin
B8: =SUMIFS(Dyn_Sales,Dyn_Region,$O$4,Dyn_Category,$O$5,Dyn_Segment,$O$6) -> 6514241 | D8: =SUMIFS(Dyn_Profit,Dyn_Region,$O$4,Dyn_Category,$O$5,Dyn_Segment,$O$6) -> 1265563.7 | F8: =COUNTIFS(Dyn_Region,$O$4,Dyn_Category,$O$5,Dyn_Segment,$O$6) -> 294 | H8: =IFERROR(B8/F8,0) -> 22157.282 | J8: =IFERROR(D8/B8,0) -> 0.19427646
B11: 📅 Monthly Trend | F11: 🏆 Product Sales | I11: 📦 Category Sales
B12: Month | C12: Sales (₹) | D12: Profit (₹) | F12: Product | G12: Sales (₹) | I12: Category | J12: Sales (₹)
A13: 1 | B13: =TEXT(DATE(2025,A13,1),"mmm") -> Jan | C13: =SUMIFS(Dyn_Sales,Dyn_MonthNo,$A13,Dyn_Region,$O$4,Dyn_Category,$O$5,Dyn_Segment,$O$6) -> 354040.5 | D13: =SUMIFS(Dyn_Profit,Dyn_MonthNo,$A13,Dyn_Region,$O$4,Dyn_Category,$O$5,Dyn_Segment,$O$6) -> 71384.55 | F13: ='🧮 Formulas'!A6 -> Laptop | G13: =SUMIFS(Dyn_Sales,Dyn_Product,$F13,Dyn_Region,$O$4,Dyn_Category,$O$5,Dyn_Segment,$O$6) -> 2367750 | I13: ='🧮 Formulas'!E6 -> Technology | J13: =SUMIFS(Dyn_Sales,Dyn_Category,$I13,Dyn_Region,$O$4,Dyn_Category,$O$5,Dyn_Segment,$O$6) -> 4656725
A14: 2 | B14: =TEXT(DATE(2025,A14,1),"mmm") -> Feb | C14: =SUMIFS(Dyn_Sales,Dyn_MonthNo,$A14,Dyn_Region,$O$4,Dyn_Category,$O$5,Dyn_Segment,$O$6) -> 375093.5 | D14: =SUMIFS(Dyn_Profit,Dyn_MonthNo,$A14,Dyn_Region,$O$4,Dyn_Category,$O$5,Dyn_Segment,$O$6) -> 75165.05 | F14: ='🧮 Formulas'!A7 -> Smartphone | G14: =SUMIFS(Dyn_Sales,Dyn_Product,$F14,Dyn_Region,$O$4,Dyn_Category,$O$5,Dyn_Segment,$O$6) -> 1281500 | I14: ='🧮 Formulas'!E7 -> Furniture | J14: =SUMIFS(Dyn_Sales,Dyn_Category,$I14,Dyn_Region,$O$4,Dyn_Category,$O$5,Dyn_Segment,$O$6) -> 1623770
A15: 3 | B15: =TEXT(DATE(2025,A15,1),"mmm") -> Mar | C15: =SUMIFS(Dyn_Sales,Dyn_MonthNo,$A15,Dyn_Region,$O$4,Dyn_Category,$O$5,Dyn_Segment,$O$6) -> 549044.5 | D15: =SUMIFS(Dyn_Profit,Dyn_MonthNo,$A15,Dyn_Region,$O$4,Dyn_Category,$O$5,Dyn_Segment,$O$6) -> 108738.15 | F15: ='🧮 Formulas'!A8 -> Headphones | G15: =SUMIFS(Dyn_Sales,Dyn_Product,$F15,Dyn_Region,$O$4,Dyn_Category,$O$5,Dyn_Segment,$O$6) -> 240975 | I15: ='🧮 Formulas'!E8 -> Office Supplies | J15: =SUMIFS(Dyn_Sales,Dyn_Category,$I15,Dyn_Region,$O$4,Dyn_Category,$O$5,Dyn_Segment,$O$6) -> 233746
A16: 4 | B16: =TEXT(DATE(2025,A16,1),"mmm") -> Apr | C16: =SUMIFS(Dyn_Sales,Dyn_MonthNo,$A16,Dyn_Region,$O$4,Dyn_Category,$O$5,Dyn_Segment,$O$6) -> 197726 | D16: =SUMIFS(Dyn_Profit,Dyn_MonthNo,$A16,Dyn_Region,$O$4,Dyn_Category,$O$5,Dyn_Segment,$O$6) -> 40950 | F16: ='🧮 Formulas'!A9 -> Monitor | G16: =SUMIFS(Dyn_Sales,Dyn_Product,$F16,Dyn_Region,$O$4,Dyn_Category,$O$5,Dyn_Segment,$O$6) -> 766500
A17: 5 | B17: =TEXT(DATE(2025,A17,1),"mmm") -> May | C17: =SUMIFS(Dyn_Sales,Dyn_MonthNo,$A17,Dyn_Region,$O$4,Dyn_Category,$O$5,Dyn_Segment,$O$6) -> 542871 | D17: =SUMIFS(Dyn_Profit,Dyn_MonthNo,$A17,Dyn_Region,$O$4,Dyn_Category,$O$5,Dyn_Segment,$O$6) -> 104217.3 | F17: ='🧮 Formulas'!A10 -> Office Chair | G17: =SUMIFS(Dyn_Sales,Dyn_Product,$F17,Dyn_Region,$O$4,Dyn_Category,$O$5,Dyn_Segment,$O$6) -> 320875 | I17: 🌍 Region Sales
A18: 6 | B18: =TEXT(DATE(2025,A18,1),"mmm") -> Jun | C18: =SUMIFS(Dyn_Sales,Dyn_MonthNo,$A18,Dyn_Region,$O$4,Dyn_Category,$O$5,Dyn_Segment,$O$6) -> 360075 | D18: =SUMIFS(Dyn_Profit,Dyn_MonthNo,$A18,Dyn_Region,$O$4,Dyn_Category,$O$5,Dyn_Segment,$O$6) -> 72913.3 | F18: ='🧮 Formulas'!A11 -> Desk | G18: =SUMIFS(Dyn_Sales,Dyn_Product,$F18,Dyn_Region,$O$4,Dyn_Category,$O$5,Dyn_Segment,$O$6) -> 699600 | I18: Region | J18: Sales (₹)
A19: 7 | B19: =TEXT(DATE(2025,A19,1),"mmm") -> Jul | C19: =SUMIFS(Dyn_Sales,Dyn_MonthNo,$A19,Dyn_Region,$O$4,Dyn_Category,$O$5,Dyn_Segment,$O$6) -> 701043 | D19: =SUMIFS(Dyn_Profit,Dyn_MonthNo,$A19,Dyn_Region,$O$4,Dyn_Category,$O$5,Dyn_Segment,$O$6) -> 132206.9 | F19: ='🧮 Formulas'!A12 -> Bookcase | G19: =SUMIFS(Dyn_Sales,Dyn_Product,$F19,Dyn_Region,$O$4,Dyn_Category,$O$5,Dyn_Segment,$O$6) -> 499525 | I19: North | J19: =SUMIFS(Dyn_Sales,Dyn_Region,$I19,Dyn_Region,$O$4,Dyn_Category,$O$5,Dyn_Segment,$O$6) -> 1922759.5
A20: 8 | B20: =TEXT(DATE(2025,A20,1),"mmm") -> Aug | C20: =SUMIFS(Dyn_Sales,Dyn_MonthNo,$A20,Dyn_Region,$O$4,Dyn_Category,$O$5,Dyn_Segment,$O$6) -> 714873 | D20: =SUMIFS(Dyn_Profit,Dyn_MonthNo,$A20,Dyn_Region,$O$4,Dyn_Category,$O$5,Dyn_Segment,$O$6) -> 138237.7 | F20: ='🧮 Formulas'!A13 -> Lamp | G20: =SUMIFS(Dyn_Sales,Dyn_Product,$F20,Dyn_Region,$O$4,Dyn_Category,$O$5,Dyn_Segment,$O$6) -> 103770 | I20: South | J20: =SUMIFS(Dyn_Sales,Dyn_Region,$I20,Dyn_Region,$O$4,Dyn_Category,$O$5,Dyn_Segment,$O$6) -> 1387188
A21: 9 | B21: =TEXT(DATE(2025,A21,1),"mmm") -> Sep | C21: =SUMIFS(Dyn_Sales,Dyn_MonthNo,$A21,Dyn_Region,$O$4,Dyn_Category,$O$5,Dyn_Segment,$O$6) -> 398278 | D21: =SUMIFS(Dyn_Profit,Dyn_MonthNo,$A21,Dyn_Region,$O$4,Dyn_Category,$O$5,Dyn_Segment,$O$6) -> 78549.8 | F21: ='🧮 Formulas'!A14 -> Notebook | G21: =SUMIFS(Dyn_Sales,Dyn_Product,$F21,Dyn_Region,$O$4,Dyn_Category,$O$5,Dyn_Segment,$O$6) -> 21270 | I21: East | J21: =SUMIFS(Dyn_Sales,Dyn_Region,$I21,Dyn_Region,$O$4,Dyn_Category,$O$5,Dyn_Segment,$O$6) -> 1495776.5
A22: 10 | B22: =TEXT(DATE(2025,A22,1),"mmm") -> Oct | C22: =SUMIFS(Dyn_Sales,Dyn_MonthNo,$A22,Dyn_Region,$O$4,Dyn_Category,$O$5,Dyn_Segment,$O$6) -> 1130928.5 | D22: =SUMIFS(Dyn_Profit,Dyn_MonthNo,$A22,Dyn_Region,$O$4,Dyn_Category,$O$5,Dyn_Segment,$O$6) -> 211676.55 | F22: ='🧮 Formulas'!A15 -> Printer Paper | G22: =SUMIFS(Dyn_Sales,Dyn_Product,$F22,Dyn_Region,$O$4,Dyn_Category,$O$5,Dyn_Segment,$O$6) -> 96367.5 | I22: West | J22: =SUMIFS(Dyn_Sales,Dyn_Region,$I22,Dyn_Region,$O$4,Dyn_Category,$O$5,Dyn_Segment,$O$6) -> 1708517
A23: 11 | B23: =TEXT(DATE(2025,A23,1),"mmm") -> Nov | C23: =SUMIFS(Dyn_Sales,Dyn_MonthNo,$A23,Dyn_Region,$O$4,Dyn_Category,$O$5,Dyn_Segment,$O$6) -> 462319 | D23: =SUMIFS(Dyn_Profit,Dyn_MonthNo,$A23,Dyn_Region,$O$4,Dyn_Category,$O$5,Dyn_Segment,$O$6) -> 92527.7 | F23: ='🧮 Formulas'!A16 -> Pen Set | G23: =SUMIFS(Dyn_Sales,Dyn_Product,$F23,Dyn_Region,$O$4,Dyn_Category,$O$5,Dyn_Segment,$O$6) -> 69812.5
A24: 12 | B24: =TEXT(DATE(2025,A24,1),"mmm") -> Dec | C24: =SUMIFS(Dyn_Sales,Dyn_MonthNo,$A24,Dyn_Region,$O$4,Dyn_Category,$O$5,Dyn_Segment,$O$6) -> 727949 | D24: =SUMIFS(Dyn_Profit,Dyn_MonthNo,$A24,Dyn_Region,$O$4,Dyn_Category,$O$5,Dyn_Segment,$O$6) -> 138996.7 | F24: ='🧮 Formulas'!A17 -> Stapler | G24: =SUMIFS(Dyn_Sales,Dyn_Product,$F24,Dyn_Region,$O$4,Dyn_Category,$O$5,Dyn_Segment,$O$6) -> 46296
B63: 🌟 Best of Luck! 🌟 ✅ Dashboard made with ❤️ in Excel by Disha Thakkar 💚
B64: 📊 📈 📉 💹 🧮 📋 📌 ✨ 🎯 🚀 🎉 🥳

Sheet 📋 Instructions
A1: 📋 EXAM INSTRUCTIONS
A3: Sr. No. | B3: Task Description | C3: Status
A4: 1 | B4: ⏱️ Time Limit: 3 hours | C4: ✅ Noted
A5: 2 | B5: 🗂️ Choose any dataset from Kaggle / UCI ML Repository | C5: ✅ Retail sales dataset used
A6: 3 | B6: 📺 Create an interactive dashboard | C6: ✅ See 📺 Dashboard
A7: 4 | B7: 📑 Complete tasks in order listed | C7: ✅ Sheets follow task order
A8: 5 | B8: 💾 Save work every 15 minutes | C8: ✅ Ctrl+S habit
A9: 6 | B9: 📤 Submit final file as 'DishaThakkar_ExcelDashboard.xlsx' | C9: ✅ File named accordingly

Sheet ✅ Tasks
A1: ✅ TASK LIST & WEIGHTAGE
A3: Sr. No. | B3: Task Description | C3: Skills Tested | D3: Time Estimate Min | E3: Weightage | F3: Status | G3: Where to find it
A4: 1 | B4: 📥 Dataset Selection & Import | C4: Data Import, Initial Cleaning | D4: 15 | E4: 0.05 | F4: ✅ Done | G4: Go to 📥 Raw_Data
A5: 2 | B5: 🧹 Data Cleaning & Preparation | C5: Remove duplicates, Handle missing values, Format data types | D5: 25 | E5: 0.1 | F5: ✅ Done | G5: Go to 🧹 Clean_Data
A6: 3 | B6: 📊 Create Pivot Tables | C6: Data Analysis, Summarization | D6: 30 | E6: 0.15 | F6: ✅ Done | G6: Go to 📊 Pivots
A7: 4 | B7: 🧮 Advanced Formulas | C7: VLOOKUP, INDEX-MATCH, IF conditions, nested functions | D7: 35 | E7: 0.15 | F7: ✅ Done | G7: Go to 🧮 Formulas
A8: 5 | B8: 📈 Data Visualization | C8: Charts, Conditional Formatting | D8: 40 | E8: 0.2 | F8: ✅ Done | G8: Go to 📈 Charts
A9: 6 | B9: 🎛️ Interactive Dashboard | C9: Slicers, Timeline, Dynamic ranges | D9: 45 | E9: 0.25 | F9: ✅ Done | G9: Go to 📺 Dashboard
A10: 7 | B10: 📝 Documentation | C10: Sheet organization, Naming conventions, Instructions | D10: 20 | E10: 0.1 | F10: ✅ Done | G10: Go to 📝 Documentation
B11: Total | D11: =SUM(D4:D10) -> 210 | E11: =SUM(E4:E10) -> 1 | F11: =COUNTIF(F4:F10,"*Done")&" / 7 ✅" -> 7 / 7 ✅
B13: Exam time limit (min) | D13: 180
B14: Estimated minutes vs. limit | D14: =D11-D13 -> 30
B15: Note: the estimates in the exam sheet add up to 210 min, which is 30 min over the 3-hour limit.

Sheet 📥 Raw_Data
A1: Order ID | B1: Order Date | C1: Region | D1: Category | E1: Product | F1: Segment | G1: Quantity | H1: Unit Price | I1: Discount
A2: ORD-1096 | B2: 45873 | C2: West | D2: Technology | E2: Headphones | F2: Consumer | G2: 1 | H2: 3500 | I2: 0.1
A3: ORD-1002 | B3: 45874 | C3: North | D3: Office Supplies | E3: Notebook | F3: Consumer | G3: 11 | H3: 120 | I3: 0
A4: ORD-1241 | B4: 45789 | C4: South | D4: Technology | E4: Laptop | F4: Consumer | G4: 1 | H4: 55000 | I4: 0.15
A5: ORD-1274 | B5: 45823 | C5: South | D5: Technology | E5: Smartphone | F5: Corporate | G5: 2 | H5: 22000 | I5: 0.15
A6: ORD-1151 | B6: 45868 | C6: South | D6: Furniture | E6: Desk | F6: Consumer | G6: 5 | H6: 12000
A7: ORD-1106 | B7: 45890 | D7: Furniture | E7: Bookcase | F7: Corporate | G7: 6 | H7: 6500 | I7: 0.05
A8: ORD-1080 | B8: 46013 | C8: South | D8: Technology | E8: Smartphone | F8: Home Office | G8: 4 | H8: 22000 | I8: 0
A9: ORD-1227 | B9: 45843 | C9: East | D9: Furniture | E9: Bookcase | F9: Consumer | G9: 1 | H9: 6500 | I9: 0
A10: ORD-1221 | B10: 45925 | C10: South | D10: Office Supplies | E10: Stapler | F10: Corporate | G10: 10 | H10: 180 | I10: 0.05
A11: ORD-1037 | B11: 45874 | C11: West | D11: Technology | E11: Monitor | F11: Consumer | G11: 3 | H11: 14000 | I11: 0
A12: ORD-1044 | B12: 45933 | C12: South | D12: Office Supplies | E12: Notebook | F12: Home Office | G12: 3 | H12: 120 | I12: 0.05
A13: ORD-1051 | B13: 45884 | C13: West | D13: Office Supplies | E13: Printer Paper | F13: Home Office | G13: 13 | H13: 450 | I13: 0
A14: ORD-1193 | B14: 45994 | C14: West | D14: Furniture | E14: Desk | F14: Consumer | G14: 2 | H14: 12000 | I14: 0
A15: ORD-1143 | B15: 2025-12-06 | C15: South | D15: Office Supplies | E15: Stapler | F15: Corporate | G15: 8 | H15: 180 | I15: 0
A16: ORD-1262 | B16: 45885 | C16: North | D16: Office Supplies | E16: Pen Set | F16: Home Office | G16: 7 | H16: 250
A17: ORD-1265 | B17: 45767 | C17: East | D17: Technology | E17: Headphones | F17: Home Office | G17: 4 | H17: 3500
A18: ORD-1011 | B18: 45931 | C18: South | D18: Technology | E18: Laptop | F18: Consumer | G18: 2 | H18: 55000 | I18: 0.1
A19: ORD-1159 | B19: 45755 | C19: East | D19: Office Supplies | E19: Printer Paper | F19: Home Office | G19: 12 | H19: 450 | I19: 0.2
A20: ORD-1207 | B20: 45952 | C20: West | D20: Furniture | E20: Office Chair | F20: Home Office | G20: 3 | H20: 8500 | I20: 0.1
A21: ORD-1211 | B21: 45697 | C21: NORTH | D21: Furniture | E21: Bookcase | F21: Home Office | G21: 2 | H21: 6500 | I21: 0.15
A22: ORD-1083 | B22: 45857 | C22: West | D22: Furniture | E22: Bookcase | F22: Home Office | G22: 3 | H22: 6500 | I22: 0.2
A23: ORD-1142 | B23: 45680 | C23: East | D23: Furniture | E23: Desk | F23: Home Office | G23: 4 | H23: 12000 | I23: 0.1
A24: ORD-1063 | B24: 2025-01-23 | C24: West | D24: Technology | E24: Smartphone | F24: Consumer | G24: 3 | H24: 22000 | I24: 0.15
A25: ORD-1026 | B25: 45922 | D25: Furniture | E25: Bookcase | F25: Consumer | G25: 4 | H25: 6500 | I25: 0
A26: ORD-1075 | B26: 2025-05-08 | C26: North | D26: Furniture | E26: Office Chair | F26: Corporate | G26: 5 | H26: 8500 | I26: 0
A27: ORD-1078 | B27: 45780 | C27: east | D27: Office Supplies | E27: Stapler | F27: Corporate | G27: 12 | H27: 180 | I27: 0
A28: ORD-1111 | B28: 45664 | C28: East | D28: Office Supplies | E28: Stapler | F28: Corporate | G28: 3 | H28: 180 | I28: 0.1
A29: ORD-1190 | B29: 45707 | C29: East | D29: Office Supplies | E29: Notebook | F29: Consumer | G29: 8 | H29: 120
A30: ORD-1183 | B30: 45863 | C30: West | D30: Office Supplies | E30: Notebook | F30: Home Office | G30: 9 | H30: 120 | I30: 0
A31: ORD-1292 | B31: 45845 | C31: South | D31: Furniture | E31: Bookcase | F31: Consumer | G31: 5 | H31: 6500 | I31: 0.15
A32: ORD-1010 | B32: 45847 | C32: East | D32: Furniture | E32: Bookcase | F32: Consumer | G32: 2 | H32: 6500 | I32: 0.2
A33: ORD-1120 | B33: 46009 | C33: South | D33: Office Supplies | E33: Stapler | F33: Corporate | G33: 3 | H33: 180 | I33: 0.2
A34: ORD-1214 | B34: 45946 | C34: West | D34: Technology | E34: Monitor | F34: Home Office | G34: 4 | H34: 14000 | I34: 0.15
A35: ORD-1092 | B35: 45743 | C35: North | D35: Furniture | E35: Bookcase | F35: Consumer | G35: 3 | H35: 6500 | I35: 0.05
A36: ORD-1050 | B36: 45659 | C36: East | D36: Furniture | E36: Bookcase | F36: Consumer | G36: 1 | H36: 6500 | I36: 0.2
A37: ORD-1048 | B37: 45967 | C37: South | D37: Furniture | E37: Bookcase | F37: Home Office | G37: 3 | H37: 6500 | I37: 0.05
A38: ORD-1125 | B38: 45823 | C38: East | D38: Furniture | E38: Lamp | F38: Consumer | G38: 6 | H38: 1800 | I38: 0
A39: ORD-1003 | B39: 45990 | C39: West | D39: Technology | E39: Laptop | F39: Consumer | G39: 2 | H39: 55000 | I39: 0.1
A40: ORD-1073 | B40: 46014 | C40: West | D40: Office Supplies | E40: Printer Paper | F40: Corporate | G40: 13 | H40: 450 | I40: 0.1
...

Sheet 🧹 Clean_Data
A1: Order ID | B1: Order Date | C1: Region | D1: Category | E1: Product | F1: Segment | G1: Quantity | H1: Unit Price | I1: Discount | J1: Sales (₹) | K1: Margin % | L1: Profit (₹) | M1: Month No | N1: Month | P1: 🧾 CLEANING LOG
A2: ORD-1050 | B2: 45659 | C2: East | D2: Furniture | E2: Bookcase | F2: Consumer | G2: 1 | H2: 6500 | I2: 0.2 | J2: =G2*H2*(1-I2) -> 5200 | K2: =INDEX('🧮 Formulas'!$F$6:$F$8,MATCH(D2,'🧮 Formulas'!$E$6:$E$8,0)) -> 0.22 | L2: =J2*K2 -> 1144 | M2: =MONTH(B2) -> 1 | N2: =TEXT(B2,"mmm") -> Jan | P2: Raw rows | Q2: =COUNTA('📥 Raw_Data'!A2:A313) -> 312
A3: ORD-1118 | B3: 45659 | C3: West | D3: Technology | E3: Laptop | F3: Corporate | G3: 2 | H3: 55000 | I3: 0.2 | J3: =G3*H3*(1-I3) -> 88000 | K3: =INDEX('🧮 Formulas'!$F$6:$F$8,MATCH(D3,'🧮 Formulas'!$E$6:$E$8,0)) -> 0.18 | L3: =J3*K3 -> 15840 | M3: =MONTH(B3) -> 1 | N3: =TEXT(B3,"mmm") -> Jan | P3: Unique Order IDs | Q3: =SUMPRODUCT(1/COUNTIF('📥 Raw_Data'!A2:A313,'📥 Raw_Data'!A2:A313)) -> 300
A4: ORD-1139 | B4: 45659 | C4: East | D4: Office Supplies | E4: Pen Set | F4: Home Office | G4: 15 | H4: 250 | I4: 0.05 | J4: =G4*H4*(1-I4) -> 3562.5 | K4: =INDEX('🧮 Formulas'!$F$6:$F$8,MATCH(D4,'🧮 Formulas'!$E$6:$E$8,0)) -> 0.3 | L4: =J4*K4 -> 1068.75 | M4: =MONTH(B4) -> 1 | N4: =TEXT(B4,"mmm") -> Jan | P4: Duplicates removed | Q4: =Q2-Q3 -> 12
A5: ORD-1102 | B5: 45663 | C5: South | D5: Office Supplies | E5: Pen Set | F5: Consumer | G5: 10 | H5: 250 | I5: 0 | J5: =G5*H5*(1-I5) -> 2500 | K5: =INDEX('🧮 Formulas'!$F$6:$F$8,MATCH(D5,'🧮 Formulas'!$E$6:$E$8,0)) -> 0.3 | L5: =J5*K5 -> 750 | M5: =MONTH(B5) -> 1 | N5: =TEXT(B5,"mmm") -> Jan | P5: Blank Region (rows dropped) | Q5: =COUNTBLANK('📥 Raw_Data'!C2:C313) -> 6
A6: ORD-1111 | B6: 45664 | C6: East | D6: Office Supplies | E6: Stapler | F6: Corporate | G6: 3 | H6: 180 | I6: 0.1 | J6: =G6*H6*(1-I6) -> 486 | K6: =INDEX('🧮 Formulas'!$F$6:$F$8,MATCH(D6,'🧮 Formulas'!$E$6:$E$8,0)) -> 0.3 | L6: =J6*K6 -> 145.8 | M6: =MONTH(B6) -> 1 | N6: =TEXT(B6,"mmm") -> Jan | P6: Missing Quantity (→ product median) | Q6: =COUNTBLANK('📥 Raw_Data'!G2:G313) -> 11
A7: ORD-1179 | B7: 45665 | C7: East | D7: Office Supplies | E7: Notebook | F7: Consumer | G7: 4 | H7: 120 | I7: 0.15 | J7: =G7*H7*(1-I7) -> 408 | K7: =INDEX('🧮 Formulas'!$F$6:$F$8,MATCH(D7,'🧮 Formulas'!$E$6:$E$8,0)) -> 0.3 | L7: =J7*K7 -> 122.4 | M7: =MONTH(B7) -> 1 | N7: =TEXT(B7,"mmm") -> Jan | P7: Missing Discount (→ 0%) | Q7: =COUNTBLANK('📥 Raw_Data'!I2:I313) -> 13
A8: ORD-1296 | B8: 45666 | C8: East | D8: Furniture | E8: Bookcase | F8: Corporate | G8: 4 | H8: 6500 | I8: 0.2 | J8: =G8*H8*(1-I8) -> 20800 | K8: =INDEX('🧮 Formulas'!$F$6:$F$8,MATCH(D8,'🧮 Formulas'!$E$6:$E$8,0)) -> 0.22 | L8: =J8*K8 -> 4576 | M8: =MONTH(B8) -> 1 | N8: =TEXT(B8,"mmm") -> Jan | P8: Clean rows | Q8: =COUNTA(A2:A295) -> 294
A9: ORD-1022 | B9: 45667 | C9: North | D9: Office Supplies | E9: Pen Set | F9: Corporate | G9: 9 | H9: 250 | I9: 0.05 | J9: =G9*H9*(1-I9) -> 2137.5 | K9: =INDEX('🧮 Formulas'!$F$6:$F$8,MATCH(D9,'🧮 Formulas'!$E$6:$E$8,0)) -> 0.3 | L9: =J9*K9 -> 641.25 | M9: =MONTH(B9) -> 1 | N9: =TEXT(B9,"mmm") -> Jan
A10: ORD-1300 | B10: 45667 | C10: West | D10: Office Supplies | E10: Notebook | F10: Corporate | G10: 5 | H10: 120 | I10: 0.1 | J10: =G10*H10*(1-I10) -> 540 | K10: =INDEX('🧮 Formulas'!$F$6:$F$8,MATCH(D10,'🧮 Formulas'!$E$6:$E$8,0)) -> 0.3 | L10: =J10*K10 -> 162 | M10: =MONTH(B10) -> 1 | N10: =TEXT(B10,"mmm") -> Jan | P10: Note: blank-Region count may include rows that were also duplicates.
A11: ORD-1286 | B11: 45669 | C11: North | D11: Furniture | E11: Bookcase | F11: Corporate | G11: 4 | H11: 6500 | I11: 0.15 | J11: =G11*H11*(1-I11) -> 22100 | K11: =INDEX('🧮 Formulas'!$F$6:$F$8,MATCH(D11,'🧮 Formulas'!$E$6:$E$8,0)) -> 0.22 | L11: =J11*K11 -> 4862 | M11: =MONTH(B11) -> 1 | N11: =TEXT(B11,"mmm") -> Jan
A12: ORD-1277 | B12: 45672 | C12: North | D12: Technology | E12: Headphones | F12: Consumer | G12: 1 | H12: 3500 | I12: 0.2 | J12: =G12*H12*(1-I12) -> 2800 | K12: =INDEX('🧮 Formulas'!$F$6:$F$8,MATCH(D12,'🧮 Formulas'!$E$6:$E$8,0)) -> 0.18 | L12: =J12*K12 -> 504 | M12: =MONTH(B12) -> 1 | N12: =TEXT(B12,"mmm") -> Jan
A13: ORD-1090 | B13: 45673 | C13: South | D13: Office Supplies | E13: Notebook | F13: Consumer | G13: 14 | H13: 120 | I13: 0 | J13: =G13*H13*(1-I13) -> 1680 | K13: =INDEX('🧮 Formulas'!$F$6:$F$8,MATCH(D13,'🧮 Formulas'!$E$6:$E$8,0)) -> 0.3 | L13: =J13*K13 -> 504 | M13: =MONTH(B13) -> 1 | N13: =TEXT(B13,"mmm") -> Jan
A14: ORD-1252 | B14: 45676 | C14: South | D14: Office Supplies | E14: Stapler | F14: Corporate | G14: 6 | H14: 180 | I14: 0.05 | J14: =G14*H14*(1-I14) -> 1026 | K14: =INDEX('🧮 Formulas'!$F$6:$F$8,MATCH(D14,'🧮 Formulas'!$E$6:$E$8,0)) -> 0.3 | L14: =J14*K14 -> 307.8 | M14: =MONTH(B14) -> 1 | N14: =TEXT(B14,"mmm") -> Jan
A15: ORD-1057 | B15: 45677 | C15: West | D15: Office Supplies | E15: Notebook | F15: Consumer | G15: 8 | H15: 120 | I15: 0 | J15: =G15*H15*(1-I15) -> 960 | K15: =INDEX('🧮 Formulas'!$F$6:$F$8,MATCH(D15,'🧮 Formulas'!$E$6:$E$8,0)) -> 0.3 | L15: =J15*K15 -> 288 | M15: =MONTH(B15) -> 1 | N15: =TEXT(B15,"mmm") -> Jan
A16: ORD-1217 | B16: 45677 | C16: North | D16: Technology | E16: Monitor | F16: Corporate | G16: 4 | H16: 14000 | I16: 0.05 | J16: =G16*H16*(1-I16) -> 53200 | K16: =INDEX('🧮 Formulas'!$F$6:$F$8,MATCH(D16,'🧮 Formulas'!$E$6:$E$8,0)) -> 0.18 | L16: =J16*K16 -> 9576 | M16: =MONTH(B16) -> 1 | N16: =TEXT(B16,"mmm") -> Jan
A17: ORD-1293 | B17: 45677 | C17: South | D17: Furniture | E17: Office Chair | F17: Home Office | G17: 1 | H17: 8500 | I17: 0.05 | J17: =G17*H17*(1-I17) -> 8075 | K17: =INDEX('🧮 Formulas'!$F$6:$F$8,MATCH(D17,'🧮 Formulas'!$E$6:$E$8,0)) -> 0.22 | L17: =J17*K17 -> 1776.5 | M17: =MONTH(B17) -> 1 | N17: =TEXT(B17,"mmm") -> Jan
A18: ORD-1006 | B18: 45680 | C18: West | D18: Office Supplies | E18: Pen Set | F18: Home Office | G18: 14 | H18: 250 | I18: 0 | J18: =G18*H18*(1-I18) -> 3500 | K18: =INDEX('🧮 Formulas'!$F$6:$F$8,MATCH(D18,'🧮 Formulas'!$E$6:$E$8,0)) -> 0.3 | L18: =J18*K18 -> 1050 | M18: =MONTH(B18) -> 1 | N18: =TEXT(B18,"mmm") -> Jan
A19: ORD-1063 | B19: 45680 | C19: West | D19: Technology | E19: Smartphone | F19: Consumer | G19: 3 | H19: 22000 | I19: 0.15 | J19: =G19*H19*(1-I19) -> 56100 | K19: =INDEX('🧮 Formulas'!$F$6:$F$8,MATCH(D19,'🧮 Formulas'!$E$6:$E$8,0)) -> 0.18 | L19: =J19*K19 -> 10098 | M19: =MONTH(B19) -> 1 | N19: =TEXT(B19,"mmm") -> Jan
A20: ORD-1142 | B20: 45680 | C20: East | D20: Furniture | E20: Desk | F20: Home Office | G20: 4 | H20: 12000 | I20: 0.1 | J20: =G20*H20*(1-I20) -> 43200 | K20: =INDEX('🧮 Formulas'!$F$6:$F$8,MATCH(D20,'🧮 Formulas'!$E$6:$E$8,0)) -> 0.22 | L20: =J20*K20 -> 9504 | M20: =MONTH(B20) -> 1 | N20: =TEXT(B20,"mmm") -> Jan
A21: ORD-1087 | B21: 45683 | C21: East | D21: Furniture | E21: Lamp | F21: Corporate | G21: 2 | H21: 1800 | I21: 0.05 | J21: =G21*H21*(1-I21) -> 3420 | K21: =INDEX('🧮 Formulas'!$F$6:$F$8,MATCH(D21,'🧮 Formulas'!$E$6:$E$8,0)) -> 0.22 | L21: =J21*K21 -> 752.4 | M21: =MONTH(B21) -> 1 | N21: =TEXT(B21,"mmm") -> Jan
A22: ORD-1180 | B22: 45684 | C22: South | D22: Furniture | E22: Desk | F22: Home Office | G22: 3 | H22: 12000 | I22: 0.1 | J22: =G22*H22*(1-I22) -> 32400 | K22: =INDEX('🧮 Formulas'!$F$6:$F$8,MATCH(D22,'🧮 Formulas'!$E$6:$E$8,0)) -> 0.22 | L22: =J22*K22 -> 7128 | M22: =MONTH(B22) -> 1 | N22: =TEXT(B22,"mmm") -> Jan
... A295: ORD-1268 | B295: 46022 | C295: South | D295: Technology | E295: Headphones | F295: Corporate | G295: 2 | H295: 3500 | I295: 0.15 | J295: =G295*H295*(1-I295) -> 5950 | K295: =INDEX('🧮 Formulas'!$F$6:$F$8,MATCH(D295,'🧮 Formulas'!$E$6:$E$8,0)) -> 0.18 | L295: =J295*K295 -> 1071 | M295: =MONTH(B295) -> 12 | N295: =TEXT(B295,"mmm") -> Dec

Sheet 📊 Pivots
A1: 📊 PIVOT-STYLE SUMMARY TABLES | SUMIFS / COUNTIFS on dynamic ranges
A2: Tables recalculate automatically when Clean_Data changes. Conditional formatting: data bars, colour scale, icon sets.
A4: 🌍 1) Sales by Region
A5: Region | B5: Orders | C5: Quantity | D5: Sales (₹) | E5: Profit (₹) | F5: % of Sales | G5: Avg Order (₹)
A6: North | B6: =COUNTIFS(Dyn_Region,$A6) -> 69 | C6: =SUMIFS(Dyn_Qty,Dyn_Region,$A6) -> 339 | D6: =SUMIFS(Dyn_Sales,Dyn_Region,$A6) -> 1922759.5 | E6: =SUMIFS(Dyn_Profit,Dyn_Region,$A6) -> 369213.65 | F6: =D6/D$10 -> 0.29516248 | G6: =IFERROR(D6/B6,0) -> 27866.08
A7: South | B7: =COUNTIFS(Dyn_Region,$A7) -> 68 | C7: =SUMIFS(Dyn_Qty,Dyn_Region,$A7) -> 314 | D7: =SUMIFS(Dyn_Sales,Dyn_Region,$A7) -> 1387188 | E7: =SUMIFS(Dyn_Profit,Dyn_Region,$A7) -> 274524.4 | F7: =D7/D$10 -> 0.21294699 | G7: =IFERROR(D7/B7,0) -> 20399.824
A8: East | B8: =COUNTIFS(Dyn_Region,$A8) -> 79 | C8: =SUMIFS(Dyn_Qty,Dyn_Region,$A8) -> 434 | D8: =SUMIFS(Dyn_Sales,Dyn_Region,$A8) -> 1495776.5 | E8: =SUMIFS(Dyn_Profit,Dyn_Region,$A8) -> 294902.55 | F8: =D8/D$10 -> 0.22961639 | G8: =IFERROR(D8/B8,0) -> 18933.88
A9: West | B9: =COUNTIFS(Dyn_Region,$A9) -> 78 | C9: =SUMIFS(Dyn_Qty,Dyn_Region,$A9) -> 409 | D9: =SUMIFS(Dyn_Sales,Dyn_Region,$A9) -> 1708517 | E9: =SUMIFS(Dyn_Profit,Dyn_Region,$A9) -> 326923.1 | F9: =D9/D$10 -> 0.26227415 | G9: =IFERROR(D9/B9,0) -> 21904.064
A10: Total | B10: =SUM(B6:B9) -> 294 | C10: =SUM(C6:C9) -> 1496 | D10: =SUM(D6:D9) -> 6514241 | E10: =SUM(E6:E9) -> 1265563.7 | F10: =SUM(F6:F9) -> 1 | G10: =IFERROR(D10/B10,0) -> 22157.282
A13: 🧩 2) Category × Region (Sales ₹)
A14: Category | B14: North | C14: South | D14: East | E14: West | F14: Total
A15: Technology | B15: =SUMIFS(Dyn_Sales,Dyn_Category,$A15,Dyn_Region,B$14) -> 1433975 | C15: =SUMIFS(Dyn_Sales,Dyn_Category,$A15,Dyn_Region,C$14) -> 864500 | D15: =SUMIFS(Dyn_Sales,Dyn_Category,$A15,Dyn_Region,D$14) -> 1006600 | E15: =SUMIFS(Dyn_Sales,Dyn_Category,$A15,Dyn_Region,E$14) -> 1351650 | F15: =SUM(B15:E15) -> 4656725
A16: Furniture | B16: =SUMIFS(Dyn_Sales,Dyn_Category,$A16,Dyn_Region,B$14) -> 444215 | C16: =SUMIFS(Dyn_Sales,Dyn_Category,$A16,Dyn_Region,C$14) -> 473650 | D16: =SUMIFS(Dyn_Sales,Dyn_Category,$A16,Dyn_Region,D$14) -> 412980 | E16: =SUMIFS(Dyn_Sales,Dyn_Category,$A16,Dyn_Region,E$14) -> 292925 | F16: =SUM(B16:E16) -> 1623770
A17: Office Supplies | B17: =SUMIFS(Dyn_Sales,Dyn_Category,$A17,Dyn_Region,B$14) -> 44569.5 | C17: =SUMIFS(Dyn_Sales,Dyn_Category,$A17,Dyn_Region,C$14) -> 49038 | D17: =SUMIFS(Dyn_Sales,Dyn_Category,$A17,Dyn_Region,D$14) -> 76196.5 | E17: =SUMIFS(Dyn_Sales,Dyn_Category,$A17,Dyn_Region,E$14) -> 63942 | F17: =SUM(B17:E17) -> 233746
A18: Total | B18: =SUM(B15:B17) -> 1922759.5 | C18: =SUM(C15:C17) -> 1387188 | D18: =SUM(D15:D17) -> 1495776.5 | E18: =SUM(E15:E17) -> 1708517 | F18: =SUM(F15:F17) -> 6514241
A21: 📅 3) Monthly Trend (2025)
A22: Month No | B22: Month | C22: Sales (₹) | D22: Profit (₹) | E22: Orders | F22: vs Monthly Avg
A23: 1 | B23: =TEXT(DATE(2025,A23,1),"mmm") -> Jan | C23: =SUMIFS(Dyn_Sales,Dyn_MonthNo,$A23) -> 354040.5 | D23: =SUMIFS(Dyn_Profit,Dyn_MonthNo,$A23) -> 71384.55 | E23: =COUNTIFS(Dyn_MonthNo,$A23) -> 23 | F23: =IFERROR(C23/AVERAGE(C$23:C$34)-1,0) -> -0.34781565
A24: 2 | B24: =TEXT(DATE(2025,A24,1),"mmm") -> Feb | C24: =SUMIFS(Dyn_Sales,Dyn_MonthNo,$A24) -> 375093.5 | D24: =SUMIFS(Dyn_Profit,Dyn_MonthNo,$A24) -> 75165.05 | E24: =COUNTIFS(Dyn_MonthNo,$A24) -> 25 | F24: =IFERROR(C24/AVERAGE(C$23:C$34)-1,0) -> -0.30903355
A25: 3 | B25: =TEXT(DATE(2025,A25,1),"mmm") -> Mar | C25: =SUMIFS(Dyn_Sales,Dyn_MonthNo,$A25) -> 549044.5 | D25: =SUMIFS(Dyn_Profit,Dyn_MonthNo,$A25) -> 108738.15 | E25: =COUNTIFS(Dyn_MonthNo,$A25) -> 22 | F25: =IFERROR(C25/AVERAGE(C$23:C$34)-1,0) -> 0.011404705
A26: 4 | B26: =TEXT(DATE(2025,A26,1),"mmm") -> Apr | C26: =SUMIFS(Dyn_Sales,Dyn_MonthNo,$A26) -> 197726 | D26: =SUMIFS(Dyn_Profit,Dyn_MonthNo,$A26) -> 40950 | E26: =COUNTIFS(Dyn_MonthNo,$A26) -> 18 | F26: =IFERROR(C26/AVERAGE(C$23:C$34)-1,0) -> -0.63576539
A27: 5 | B27: =TEXT(DATE(2025,A27,1),"mmm") -> May | C27: =SUMIFS(Dyn_Sales,Dyn_MonthNo,$A27) -> 542871 | D27: =SUMIFS(Dyn_Profit,Dyn_MonthNo,$A27) -> 104217.3 | E27: =COUNTIFS(Dyn_MonthNo,$A27) -> 32 | F27: =IFERROR(C27/AVERAGE(C$23:C$34)-1,0) -> 3.2390573e-05
A28: 6 | B28: =TEXT(DATE(2025,A28,1),"mmm") -> Jun | C28: =SUMIFS(Dyn_Sales,Dyn_MonthNo,$A28) -> 360075 | D28: =SUMIFS(Dyn_Profit,Dyn_MonthNo,$A28) -> 72913.3 | E28: =COUNTIFS(Dyn_MonthNo,$A28) -> 18 | F28: =IFERROR(C28/AVERAGE(C$23:C$34)-1,0) -> -0.33669939
A29: 7 | B29: =TEXT(DATE(2025,A29,1),"mmm") -> Jul | C29: =SUMIFS(Dyn_Sales,Dyn_MonthNo,$A29) -> 701043 | D29: =SUMIFS(Dyn_Profit,Dyn_MonthNo,$A29) -> 132206.9 | E29: =COUNTIFS(Dyn_MonthNo,$A29) -> 23 | F29: =IFERROR(C29/AVERAGE(C$23:C$34)-1,0) -> 0.29140386
A30: 8 | B30: =TEXT(DATE(2025,A30,1),"mmm") -> Aug | C30: =SUMIFS(Dyn_Sales,Dyn_MonthNo,$A30) -> 714873 | D30: =SUMIFS(Dyn_Profit,Dyn_MonthNo,$A30) -> 138237.7 | E30: =COUNTIFS(Dyn_MonthNo,$A30) -> 32 | F30: =IFERROR(C30/AVERAGE(C$23:C$34)-1,0) -> 0.31688035
A31: 9 | B31: =TEXT(DATE(2025,A31,1),"mmm") -> Sep | C31: =SUMIFS(Dyn_Sales,Dyn_MonthNo,$A31) -> 398278 | D31: =SUMIFS(Dyn_Profit,Dyn_MonthNo,$A31) -> 78549.8 | E31: =COUNTIFS(Dyn_MonthNo,$A31) -> 19 | F31: =IFERROR(C31/AVERAGE(C$23:C$34)-1,0) -> -0.26632496
A32: 10 | B32: =TEXT(DATE(2025,A32,1),"mmm") -> Oct | C32: =SUMIFS(Dyn_Sales,Dyn_MonthNo,$A32) -> 1130928.5 | D32: =SUMIFS(Dyn_Profit,Dyn_MonthNo,$A32) -> 211676.55 | E32: =COUNTIFS(Dyn_MonthNo,$A32) -> 34 | F32: =IFERROR(C32/AVERAGE(C$23:C$34)-1,0) -> 1.0833036
A33: 11 | B33: =TEXT(DATE(2025,A33,1),"mmm") -> Nov | C33: =SUMIFS(Dyn_Sales,Dyn_MonthNo,$A33) -> 462319 | D33: =SUMIFS(Dyn_Profit,Dyn_MonthNo,$A33) -> 92527.7 | E33: =COUNTIFS(Dyn_MonthNo,$A33) -> 18 | F33: =IFERROR(C33/AVERAGE(C$23:C$34)-1,0) -> -0.14835389
A34: 12 | B34: =TEXT(DATE(2025,A34,1),"mmm") -> Dec | C34: =SUMIFS(Dyn_Sales,Dyn_MonthNo,$A34) -> 727949 | D34: =SUMIFS(Dyn_Profit,Dyn_MonthNo,$A34) -> 138996.7 | E34: =COUNTIFS(Dyn_MonthNo,$A34) -> 30 | F34: =IFERROR(C34/AVERAGE(C$23:C$34)-1,0) -> 0.34096789
A35: Total | C35: =SUM(C23:C34) -> 6514241 | D35: =SUM(D23:D34) -> 1265563.7 | E35: =SUM(E23:E34) -> 294
A38: 🏆 4) Product Performance
A39: Product | B39: Category | C39: Quantity | D39: Sales (₹) | E39: Profit (₹) | F39: Rank
A40: ='🧮 Formulas'!A6 -> Laptop | B40: =INDEX('🧮 Formulas'!$B$6:$B$17,MATCH(A40,'🧮 Formulas'!$A$6:$A$17,0)) -> Technology | C40: =SUMIFS(Dyn_Qty,Dyn_Product,$A40) -> 48 | D40: =SUMIFS(Dyn_Sales,Dyn_Product,$A40) -> 2367750 | E40: =SUMIFS(Dyn_Profit,Dyn_Product,$A40) -> 426195 | F40: =RANK(D40,$D$40:$D$51) -> 1
A41: ='🧮 Formulas'!A7 -> Smartphone | B41: =INDEX('🧮 Formulas'!$B$6:$B$17,MATCH(A41,'🧮 Formulas'!$A$6:$A$17,0)) -> Technology | C41: =SUMIFS(Dyn_Qty,Dyn_Product,$A41) -> 63 | D41: =SUMIFS(Dyn_Sales,Dyn_Product,$A41) -> 1281500 | E41: =SUMIFS(Dyn_Profit,Dyn_Product,$A41) -> 230670 | F41: =RANK(D41,$D$40:$D$51) -> 2
A42: ='🧮 Formulas'!A8 -> Headphones | B42: =INDEX('🧮 Formulas'!$B$6:$B$17,MATCH(A42,'🧮 Formulas'!$A$6:$A$17,0)) -> Technology | C42: =SUMIFS(Dyn_Qty,Dyn_Product,$A42) -> 75 | D42: =SUMIFS(Dyn_Sales,Dyn_Product,$A42) -> 240975 | E42: =SUMIFS(Dyn_Profit,Dyn_Product,$A42) -> 43375.5 | F42: =RANK(D42,$D$40:$D$51) -> 7
A43: ='🧮 Formulas'!A9 -> Monitor | B43: =INDEX('🧮 Formulas'!$B$6:$B$17,MATCH(A43,'🧮 Formulas'!$A$6:$A$17,0)) -> Technology | C43: =SUMIFS(Dyn_Qty,Dyn_Product,$A43) -> 61 | D43: =SUMIFS(Dyn_Sales,Dyn_Product,$A43) -> 766500 | E43: =SUMIFS(Dyn_Profit,Dyn_Product,$A43) -> 137970 | F43: =RANK(D43,$D$40:$D$51) -> 3
A44: ='🧮 Formulas'!A10 -> Office Chair | B44: =INDEX('🧮 Formulas'!$B$6:$B$17,MATCH(A44,'🧮 Formulas'!$A$6:$A$17,0)) -> Furniture | C44: =SUMIFS(Dyn_Qty,Dyn_Product,$A44) -> 41 | D44: =SUMIFS(Dyn_Sales,Dyn_Product,$A44) -> 320875 | E44: =SUMIFS(Dyn_Profit,Dyn_Product,$A44) -> 70592.5 | F44: =RANK(D44,$D$40:$D$51) -> 6
A45: ='🧮 Formulas'!A11 -> Desk | B45: =INDEX('🧮 Formulas'!$B$6:$B$17,MATCH(A45,'🧮 Formulas'!$A$6:$A$17,0)) -> Furniture | C45: =SUMIFS(Dyn_Qty,Dyn_Product,$A45) -> 61 | D45: =SUMIFS(Dyn_Sales,Dyn_Product,$A45) -> 699600 | E45: =SUMIFS(Dyn_Profit,Dyn_Product,$A45) -> 153912 | F45: =RANK(D45,$D$40:$D$51) -> 4
A46: ='🧮 Formulas'!A12 -> Bookcase | B46: =INDEX('🧮 Formulas'!$B$6:$B$17,MATCH(A46,'🧮 Formulas'!$A$6:$A$17,0)) -> Furniture | C46: =SUMIFS(Dyn_Qty,Dyn_Product,$A46) -> 84 | D46: =SUMIFS(Dyn_Sales,Dyn_Product,$A46) -> 499525 | E46: =SUMIFS(Dyn_Profit,Dyn_Product,$A46) -> 109895.5 | F46: =RANK(D46,$D$40:$D$51) -> 5
A47: ='🧮 Formulas'!A13 -> Lamp | B47: =INDEX('🧮 Formulas'!$B$6:$B$17,MATCH(A47,'🧮 Formulas'!$A$6:$A$17,0)) -> Furniture | C47: =SUMIFS(Dyn_Qty,Dyn_Product,$A47) -> 63 | D47: =SUMIFS(Dyn_Sales,Dyn_Product,$A47) -> 103770 | E47: =SUMIFS(Dyn_Profit,Dyn_Product,$A47) -> 22829.4 | F47: =RANK(D47,$D$40:$D$51) -> 8
...

Sheet 🧮 Formulas
A1: 🧮 ADVANCED FORMULAS | VLOOKUP • INDEX-MATCH • IF • Nested Functions
A3: 🔑 Yellow cells = inputs you can change | Blue text = assumptions (hardcoded inputs)
A4: 📦 Product Master (lookup table) | E4: 💰 Category Margin %
A5: Product | B5: Category | C5: List Price (₹) | E5: Category | F5: Margin %
A6: Laptop | B6: Technology | C6: 55000 | E6: Technology | F6: 0.18
A7: Smartphone | B7: Technology | C7: 22000 | E7: Furniture | F7: 0.22
A8: Headphones | B8: Technology | C8: 3500 | E8: Office Supplies | F8: 0.3
A9: Monitor | B9: Technology | C9: 14000 | E9: Assumption: margins are illustrative inputs set by the student.
A10: Office Chair | B10: Furniture | C10: 8500
A11: Desk | B11: Furniture | C11: 12000
A12: Bookcase | B12: Furniture | C12: 6500
A13: Lamp | B13: Furniture | C13: 1800
A14: Notebook | B14: Office Supplies | C14: 120
A15: Printer Paper | B15: Office Supplies | C15: 450
A16: Pen Set | B16: Office Supplies | C16: 250
A17: Stapler | B17: Office Supplies | C17: 180
A20: 🔍 LOOKUP DEMO
A21: Pick a product 👉 | B21: Laptop
A22: Category | B22: =VLOOKUP($B$21,$A$6:$C$17,2,FALSE()) -> Technology | C22: 🏷️ VLOOKUP
A23: List Price | B23: =VLOOKUP($B$21,$A$6:$C$17,3,FALSE()) -> 55000 | C23: 🏷️ VLOOKUP
A24: List Price (again) | B24: =INDEX($C$6:$C$17,MATCH($B$21,$A$6:$A$17,0)) -> 55000 | C24: 🏷️ INDEX-MATCH
A25: Margin % | B25: =INDEX($F$6:$F$8,MATCH(B22,$E$6:$E$8,0)) -> 0.18 | C25: 🏷️ Nested lookup
A26: Units Sold | B26: =SUMIFS(Dyn_Qty,Dyn_Product,$B$21) -> 48 | C26: 🏷️ SUMIFS + named range
A27: Total Sales | B27: =SUMIFS(Dyn_Sales,Dyn_Product,$B$21) -> 2367750 | C27: 🏷️ SUMIFS
A28: Sales Rank (of 12) | B28: =INDEX('📊 Pivots'!$F$40:$F$51,MATCH($B$21,'📊 Pivots'!$A$40:$A$51,0)) -> 1 | C28: 🏷️ INDEX-MATCH across sheets
A29: Rating | B29: =IF(B28<=3,"⭐ Top Seller",IF(B28<=8,"👍 Average","⚠️ Needs a Push")) -> ⭐ Top Seller | C29: 🏷️ Nested IF
A32: 🎯 REGION SCORECARD
A33: Region | B33: Sales (₹) | C33: Target (₹) | D33: Achievement % | E33: Status
A34: North | B34: =INDEX('📊 Pivots'!$D$6:$D$9,MATCH(A34,'📊 Pivots'!$A$6:$A$9,0)) -> 1922759.5 | C34: 2100000 | D34: =IFERROR(B34/C34,0) -> 0.91559976 | E34: =IF(D34>=1,"🏆 Target Achieved",IF(D34>=0.9,"🟡 Almost There","🔴 Below Target")) -> 🟡 Almost There
A35: South | B35: =INDEX('📊 Pivots'!$D$6:$D$9,MATCH(A35,'📊 Pivots'!$A$6:$A$9,0)) -> 1387188 | C35: 1300000 | D35: =IFERROR(B35/C35,0) -> 1.0670677 | E35: =IF(D35>=1,"🏆 Target Achieved",IF(D35>=0.9,"🟡 Almost There","🔴 Below Target")) -> 🏆 Target Achieved
A36: East | B36: =INDEX('📊 Pivots'!$D$6:$D$9,MATCH(A36,'📊 Pivots'!$A$6:$A$9,0)) -> 1495776.5 | C36: 1500000 | D36: =IFERROR(B36/C36,0) -> 0.99718433 | E36: =IF(D36>=1,"🏆 Target Achieved",IF(D36>=0.9,"🟡 Almost There","🔴 Below Target")) -> 🟡 Almost There
A37: West | B37: =INDEX('📊 Pivots'!$D$6:$D$9,MATCH(A37,'📊 Pivots'!$A$6:$A$9,0)) -> 1708517 | C37: 1500000 | D37: =IFERROR(B37/C37,0) -> 1.1390113 | E37: =IF(D37>=1,"🏆 Target Achieved",IF(D37>=0.9,"🟡 Almost There","🔴 Below Target")) -> 🏆 Target Achieved
A38: Assumption: targets are illustrative inputs (blue) set by the student.
A40: 🧠 OTHER FUNCTIONS
A41: Total discount given | B41: =SUMPRODUCT(Dyn_Qty,Dyn_Price,Dyn_Disc) -> 621649 | C41: 🏷️ SUMPRODUCT
A42: Orders with discount ≥ 10% | B42: =COUNTIFS(Dyn_Disc,">=0.1") -> 145 | C42: 🏷️ COUNTIFS
A43: Average discount | B43: =AVERAGE(Dyn_Disc) -> 0.080272109 | C43: 🏷️ AVERAGE
A44: Best month 🏅 | B44: =INDEX('📊 Pivots'!$B$23:$B$34,MATCH(MAX('📊 Pivots'!$C$23:$C$34),'📊 Pivots'!$C$23:$C$34,0)) -> Oct | C44: 🏷️ INDEX + MATCH + MAX
A45: Best region 🌟 | B45: =INDEX('📊 Pivots'!$A$6:$A$9,MATCH(MAX('📊 Pivots'!$D$6:$D$9),'📊 Pivots'!$D$6:$D$9,0)) -> North | C45: 🏷️ INDEX + MATCH + MAX
A46: Lookup with error handling | B46: =IFERROR(VLOOKUP("Tablet",$A$6:$C$17,3,FALSE()),"Not found ❌") -> Not found ❌ | C46: 🏷️ IFERROR + VLOOKUP
...

Sheet 📈 Charts
A1: 📈 DATA VISUALIZATION | Charts (linked to 📊 Pivots)
A2: Conditional formatting (data bars 📊, colour scale 🎨, icon arrows ⬆️⬇️, top/bottom highlights) is applied on the 📊 Pivots sheet.

Sheet 📝 Documentation
A1: 📝 DOCUMENTATION
A3: Topic | B3: Details | C3: Sheet
A4: 📌 Purpose | B4: Interactive sales dashboard built for the Final Practical Exam (3 hours). | C4: 📺 Dashboard
A5: 🗂️ Dataset | B5: Sample retail sales data (300 orders, 12 products, 4 regions, year 2025). Generated to mimic a Kaggle-style sales file, because no download was possible here. To use a real Kaggle/UCI file, paste it into 📥 Raw_Data with the same 9 columns. | C5: 📥 Raw_Data
A6: 🧹 Cleaning steps | B6: 1) Removed duplicate Order IDs 2) TRIM + proper case on Region 3) Rows with blank Region dropped 4) Missing Quantity → product median 5) Missing Discount → 0% 6) Text dates/quantities converted to real dates/numbers. Counts in the Cleaning Log. | C6: 🧹 Clean_Data
A7: 🧮 Calculated columns | B7: Sales = Qty × Unit Price × (1 − Discount) · Margin % = INDEX-MATCH on category · Profit = Sales × Margin % · Month = MONTH()/TEXT(). | C7: 🧹 Clean_Data
A8: 📊 Pivot tables | B8: Built with SUMIFS/COUNTIFS so they refresh automatically. For a native PivotTable: select Clean_Data → Insert → PivotTable. | C8: 📊 Pivots
A9: 📏 Dynamic ranges | B9: Named ranges Dyn_* use OFFSET + COUNTA, so formulas grow automatically when rows are added to Clean_Data. | C9: 🧹 Clean_Data
A10: 📈 Charts | B10: Six charts on 📈 Charts and four on the dashboard; all linked to formula tables. | C10: 📈 Charts
A11: 🎛️ Dashboard filters | B11: Yellow dropdowns (Region, Category, Segment) drive every KPI and chart. 'All' is turned into the * wildcard in helper cells. To add a native Slicer in Excel: PivotTable → Insert Slicer / Timeline. | C11: 📺 Dashboard
A12: 🏷️ Naming conventions | B12: Sheets are numbered by task order with an emoji prefix. Named ranges start with Dyn_. Blue text = hardcoded assumption, black = formula, yellow fill = input cell. | C12: 🏠 Cover
A13: ⚠️ Assumptions | B13: Category margins and region targets on 🧮 Formulas are illustrative inputs. Currency is INR (₹). Data covers Jan–Dec 2025. | C13: 🧮 Formulas
A14: 💾 Saving | B14: Save every 15 minutes (Ctrl+S) and submit as DishaThakkar_ExcelDashboard.xlsx. | C14: 🏠 Cover
